const { HttpException } = require('../model/http-exception')
/**
 * 捕获错误
 */
const catchError = async (ctx, next) => {
  try {
    await next()
  } catch (error) {
    // 开发环境 生产环境 有区别
    // 抛出异常条件 开发环境 且 不是HttpException
    const isHttpException = error instanceof HttpException

    // if (global.config.isDev && !isHttpException) {
    if ( !isHttpException) {
      throw error
    }
    // 已知异常
    if (isHttpException) {
      ctx.body = {
        msg: error.msg,
        error_code: error.errorCode,
        request: `${ctx.method} ${ctx.path}`
      }
      ctx.status = error.status
    } else {
      // 未知异常
      ctx.body = {
        msg: 'we made a mistake, unknown error O(∩_∩)O~~',
        error_code: 999,
        request: `${ctx.method} ${ctx.path}`
      }
      ctx.status = 500
    }
    /**
     * error 堆栈调用信息
     * error 简化清晰明了的信息,给前端
     * Http Status Code 2xx,4xx,5xx
     **返回的信息
     *  message
     *  error_code 详细,开发者自己定义的 10001 20003
     *  request_url 当前请求的url
     **错误类型
     *  *已知型错误
     *    参数校验错误
     *    明确处理错误
     *    try catch
     **未知型错误
     *    程序潜在的错误,无意识的,根本就不知道他出错了
     *    连接数据库时,账号密码输错了
     */
  }
}

module.exports = catchError
